Workbook

Sheet Gantt Cutover
A1: Gantt de cutover — Portland Colombia (Go-Live 09-11-2026)
A2: Base: plan de cutover acordado (Cutover_Colombia_GoLive_09Nov.pptx) y buenas prácticas SAP Activate. Edite solo las columnas Estado y Comentarios (amarillas).
A3: ="Fecha de consulta: "&TEXT(Hoy!$C$4,"dd-mm-yyyy")&" · Equipo de proyecto en Bogotá del 02 al 12-11 · Feriados de Colombia sombreados" -> Fecha de consulta: 28-10-2026 · Equipo de proyecto en Bogotá del 02 al 12-11 · Feriados de Colombia sombreados | P3: Octubre | AB3: Noviembre
P4: M | Q4: M | R4: J | S4: V | T4: S | U4: D | V4: L | W4: M | X4: M | Y4: J | Z4: V | AA4: S | AB4: D | AC4: L | AD4: M | AE4: M | AF4: J | AG4: V | AH4: S | AI4: D | AJ4: L | AK4: M | AL4: M | AM4: J | AN4: V | AO4: S | AP4: D | AQ4: L | AR4: M | AS4: M | AT4: J | AU4: V
A5: ID | B5: Fase | C5: Actividad / hito | D5: Tipo | E5: Detalle / entregable | F5: Frente | G5: Responsable | H5: Participantes | I5: Modalidad | J5: Inicio | K5: Fin | L5: Días | M5: Estado | N5: Alerta | O5: Comentarios | P5: 46315 | Q5: 46316 | R5: 46317 | S5: 46318 | T5: 46319 | U5: 46320 | V5: 46321 | W5: 46322 | X5: 46323 | Y5: 46324 | Z5: 46325 | AA5: 46326 | AB5: 46327 | AC5: 46328 | AD5: 46329 | AE5: 46330 | AF5: 46331 | AG5: 46332 | AH5: 46333 | AI5: 46334 | AJ5: 46335 | AK5: 46336 | AL5: 46337 | AM5: 46338 | AN5: 46339 | AO5: 46340 | AP5: 46341 | AQ5: 46342 | AR5: 46343 | AS5: 46344 | AT5: 46345 | AU5: 46346 | AW5: es_act | AX5: hoy | AY5: n_hoy | AZ5: venc | BA5: n_venc
A6: 0 | B6: 0. Equipo de proyecto en Colombia | C6: Equipo de proyecto en Colombia | D6: Fase | J6: =MIN(J7:J11) -> 46328 | K6: =MAX(K7:K11) -> 46346 | L6: =K6-J6+1 -> 19 | M6: =IF(COUNTIF(M7:M11,"Finalizado")=ROWS(M7:M11),"Finalizado",IF(OR(COUNTIF(M7:M11,"Demorado")>0,COUNTIF(N7:N11,"Vencida")>0),"Demorado",IF(COUNTIF(M7:M11,"En curso")+COUNTIF(M7:M11,"Finalizado")>0,"En curso","No iniciado"))) -> No iniciado | N6: =IF(COUNTIF(N7:N11,"Vencida")>0,COUNTIF(N7:N11,"Vencida")&" vencida(s)","") | O6: =COUNTIF(M7:M11,"Finalizado")&" de "&ROWS(M7:M11)&" finalizadas" -> 0 de 5 finalizadas | AW6: 0
A7: C01 | B7: 0. Equipo de proyecto en Colombia | C7: Equipo de proyecto en Bogotá | D7: Actividad | E7: Germán Faundes, Daniela Correa, Oscar Sella y Gabriel Salinas: preparación, carga, Go-Live y primera semana de Hypercare. | F7: PMO | G7: Gerente de Proyecto | H7: Gerente de Contabilidad Regional; TI Portland FICO; PMO Portland | I7: Presencial | J7: 46328 | K7: 46338 | L7: =K7-J7+1 -> 11 | M7: No iniciado | N7: =IF(M7="Finalizado","",IF(K7<Hoy!$C$4,"Vencida",IF(AND(J7<=Hoy!$C$4,M7="No iniciado"),"Sin iniciar",""))) | P7: =IF(AND($D7="Hito",P$5=$J7),"◆","") | Q7: =IF(AND($D7="Hito",Q$5=$J7),"◆","") | R7: =IF(AND($D7="Hito",R$5=$J7),"◆","") | S7: =IF(AND($D7="Hito",S$5=$J7),"◆","") | T7: =IF(AND($D7="Hito",T$5=$J7),"◆","") | U7: =IF(AND($D7="Hito",U$5=$J7),"◆","") | V7: =IF(AND($D7="Hito",V$5=$J7),"◆","") | W7: =IF(AND($D7="Hito",W$5=$J7),"◆","") | ... AU7: =IF(AND($D7="Hito",AU$5=$J7),"◆","") | AW7: 1 | AX7: =IF(AND(J7<=Hoy!$C$4,K7>=Hoy!$C$4),1,0) -> 0 | AY7: =IF(AX7=1,SUM($AX$6:AX7),"") | AZ7: =IF(N7="Vencida",1,0) -> 0 | BA7: =IF(AZ7=1,SUM($AZ$6:AZ7),"")
A8: C02 | B8: 0. Equipo de proyecto en Colombia | C8: Visita del Gerente General | D8: Actividad | E8: Daniel Yung: acompañamiento de Go / No-Go y Go-Live. | F8: PMO | G8: Gerente General | H8: Gerente de Proyecto | I8: Presencial | J8: 46334 | K8: 46336 | L8: =K8-J8+1 -> 3 | M8: No iniciado | N8: =IF(M8="Finalizado","",IF(K8<Hoy!$C$4,"Vencida",IF(AND(J8<=Hoy!$C$4,M8="No iniciado"),"Sin iniciar",""))) | P8: =IF(AND($D8="Hito",P$5=$J8),"◆","") | Q8: =IF(AND($D8="Hito",Q$5=$J8),"◆","") | R8: =IF(AND($D8="Hito",R$5=$J8),"◆","") | S8: =IF(AND($D8="Hito",S$5=$J8),"◆","") | T8: =IF(AND($D8="Hito",T$5=$J8),"◆","") | U8: =IF(AND($D8="Hito",U$5=$J8),"◆","") | V8: =IF(AND($D8="Hito",V$5=$J8),"◆","") | W8: =IF(AND($D8="Hito",W$5=$J8),"◆","") | ... AU8: =IF(AND($D8="Hito",AU$5=$J8),"◆","") | AW8: 1 | AX8: =IF(AND(J8<=Hoy!$C$4,K8>=Hoy!$C$4),1,0) -> 0 | AY8: =IF(AX8=1,SUM($AX$6:AX8),"") | AZ8: =IF(N8="Vencida",1,0) -> 0 | BA8: =IF(AZ8=1,SUM($AZ$6:AZ8),"")
A9: C03 | B9: 0. Equipo de proyecto en Colombia | C9: Apoyo externo para migración – 1ª visita | D9: Actividad | E9: Sebastián Salom: preparación y ejecución de la carga de datos maestros y saldos iniciales. | F9: PMO | G9: Externo – Migración | H9: Gerente de Contabilidad Regional | I9: Presencial | J9: 46329 | K9: 46332 | L9: =K9-J9+1 -> 4 | M9: No iniciado | N9: =IF(M9="Finalizado","",IF(K9<Hoy!$C$4,"Vencida",IF(AND(J9<=Hoy!$C$4,M9="No iniciado"),"Sin iniciar",""))) | P9: =IF(AND($D9="Hito",P$5=$J9),"◆","") | Q9: =IF(AND($D9="Hito",Q$5=$J9),"◆","") | R9: =IF(AND($D9="Hito",R$5=$J9),"◆","") | S9: =IF(AND($D9="Hito",S$5=$J9),"◆","") | T9: =IF(AND($D9="Hito",T$5=$J9),"◆","") | U9: =IF(AND($D9="Hito",U$5=$J9),"◆","") | V9: =IF(AND($D9="Hito",V$5=$J9),"◆","") | W9: =IF(AND($D9="Hito",W$5=$J9),"◆","") | ... AU9: =IF(AND($D9="Hito",AU$5=$J9),"◆","") | AW9: 1 | AX9: =IF(AND(J9<=Hoy!$C$4,K9>=Hoy!$C$4),1,0) -> 0 | AY9: =IF(AX9=1,SUM($AX$6:AX9),"") | AZ9: =IF(N9="Vencida",1,0) -> 0 | BA9: =IF(AZ9=1,SUM($AZ$6:AZ9),"")
A10: C04 | B10: 0. Equipo de proyecto en Colombia | C10: Apoyo externo para migración – 2ª visita | D10: Actividad | E10: Sebastián Salom: apoyo a la regularización y cuadraturas post Go-Live. | F10: PMO | G10: Externo – Migración | H10: Gerente de Contabilidad Regional | I10: Presencial | J10: 46335 | K10: 46338 | L10: =K10-J10+1 -> 4 | M10: No iniciado | N10: =IF(M10="Finalizado","",IF(K10<Hoy!$C$4,"Vencida",IF(AND(J10<=Hoy!$C$4,M10="No iniciado"),"Sin iniciar",""))) | P10: =IF(AND($D10="Hito",P$5=$J10),"◆","") | Q10: =IF(AND($D10="Hito",Q$5=$J10),"◆","") | R10: =IF(AND($D10="Hito",R$5=$J10),"◆","") | S10: =IF(AND($D10="Hito",S$5=$J10),"◆","") | T10: =IF(AND($D10="Hito",T$5=$J10),"◆","") | U10: =IF(AND($D10="Hito",U$5=$J10),"◆","") | V10: =IF(AND($D10="Hito",V$5=$J10),"◆","") | W10: =IF(AND($D10="Hito",W$5=$J10),"◆","") | ... AU10: =IF(AND($D10="Hito",AU$5=$J10),"◆","") | AW10: 1 | AX10: =IF(AND(J10<=Hoy!$C$4,K10>=Hoy!$C$4),1,0) -> 0 | AY10: =IF(AX10=1,SUM($AX$6:AX10),"") | AZ10: =IF(N10="Vencida",1,0) -> 0 | BA10: =IF(AZ10=1,SUM($AZ$6:AZ10),"")
A11: C05 | B11: 0. Equipo de proyecto en Colombia | C11: Soporte adicional post Go-Live | D11: Actividad | E11: Alonso Cuba (Portland TI Perú): soporte en sitio durante la segunda semana de Hypercare. | F11: PMO | G11: TI Portland Perú | H11: Gerente de Proyecto | I11: Presencial | J11: 46341 | K11: 46346 | L11: =K11-J11+1 -> 6 | M11: No iniciado | N11: =IF(M11="Finalizado","",IF(K11<Hoy!$C$4,"Vencida",IF(AND(J11<=Hoy!$C$4,M11="No iniciado"),"Sin iniciar",""))) | P11: =IF(AND($D11="Hito",P$5=$J11),"◆","") | Q11: =IF(AND($D11="Hito",Q$5=$J11),"◆","") | R11: =IF(AND($D11="Hito",R$5=$J11),"◆","") | S11: =IF(AND($D11="Hito",S$5=$J11),"◆","") | T11: =IF(AND($D11="Hito",T$5=$J11),"◆","") | U11: =IF(AND($D11="Hito",U$5=$J11),"◆","") | V11: =IF(AND($D11="Hito",V$5=$J11),"◆","") | W11: =IF(AND($D11="Hito",W$5=$J11),"◆","") | ... AU11: =IF(AND($D11="Hito",AU$5=$J11),"◆","") | AW11: 1 | AX11: =IF(AND(J11<=Hoy!$C$4,K11>=Hoy!$C$4),1,0) -> 0 | AY11: =IF(AX11=1,SUM($AX$6:AX11),"") | AZ11: =IF(N11="Vencida",1,0) -> 0 | BA11: =IF(AZ11=1,SUM($AZ$6:AZ11),"")
A12: 1 | B12: 1. Pruebas y Validación Modelos de Negocios | C12: Pruebas y Validación Modelos de Negocios | D12: Fase | J12: =MIN(J13:J15) -> 46321 | K12: =MAX(K13:K15) -> 46325 | L12: =K12-J12+1 -> 5 | M12: =IF(COUNTIF(M13:M15,"Finalizado")=ROWS(M13:M15),"Finalizado",IF(OR(COUNTIF(M13:M15,"Demorado")>0,COUNTIF(N13:N15,"Vencida")>0),"Demorado",IF(COUNTIF(M13:M15,"En curso")+COUNTIF(M13:M15,"Finalizado")>0,"En curso","No iniciado"))) -> En curso | N12: =IF(COUNTIF(N13:N15,"Vencida")>0,COUNTIF(N13:N15,"Vencida")&" vencida(s)","") | O12: =COUNTIF(M13:M15,"Finalizado")&" de "&ROWS(M13:M15)&" finalizadas" -> 0 de 3 finalizadas | AW12: 0
A13: C06 | B13: 1. Pruebas y Validación Modelos de Negocios | C13: Pruebas y ajustes a Modelos de Negocio | D13: Actividad | E13: Pruebas y ajustes de escenarios. | F13: Negocio | G13: Jefe de Implementación | H13: Implementador – Consultor FI/CO; Implementador – Consultor MM/SD; TI Portland FICO; TI Portland MM; Contabilidad Colombia; Comercial / Facturación Colombia; Logística / Bodega Colombia | I13: Remoto | J13: 46321 | K13: 46325 | L13: =K13-J13+1 -> 5 | M13: En curso | N13: =IF(M13="Finalizado","",IF(K13<Hoy!$C$4,"Vencida",IF(AND(J13<=Hoy!$C$4,M13="No iniciado"),"Sin iniciar",""))) | P13: =IF(AND($D13="Hito",P$5=$J13),"◆","") | Q13: =IF(AND($D13="Hito",Q$5=$J13),"◆","") | R13: =IF(AND($D13="Hito",R$5=$J13),"◆","") | S13: =IF(AND($D13="Hito",S$5=$J13),"◆","") | T13: =IF(AND($D13="Hito",T$5=$J13),"◆","") | U13: =IF(AND($D13="Hito",U$5=$J13),"◆","") | V13: =IF(AND($D13="Hito",V$5=$J13),"◆","") | W13: =IF(AND($D13="Hito",W$5=$J13),"◆","") | ... AU13: =IF(AND($D13="Hito",AU$5=$J13),"◆","") | AW13: 1 | AX13: =IF(AND(J13<=Hoy!$C$4,K13>=Hoy!$C$4),1,0) -> 1 | AY13: =IF(AX13=1,SUM($AX$6:AX13),"") -> 1 | AZ13: =IF(N13="Vencida",1,0) -> 0 | BA13: =IF(AZ13=1,SUM($AZ$6:AZ13),"")
A14: C07 | B14: 1. Pruebas y Validación Modelos de Negocios | C14: Pruebas y Ajustes a FFEE | D14: Actividad | E14: Los 4 escenarios de Documentos Electrónicos aprobador por DIAN y el Negocio. (Distribución, Exportacion, Nota Credito, Nota Débito) | F14: Localización-FFEE | G14: Jefe de Implementación | H14: TI Portland SD y FFEE; Implementador – FFEE/Formularios | I14: Remoto | J14: 46321 | K14: 46325 | L14: =K14-J14+1 -> 5 | M14: En curso | N14: =IF(M14="Finalizado","",IF(K14<Hoy!$C$4,"Vencida",IF(AND(J14<=Hoy!$C$4,M14="No iniciado"),"Sin iniciar",""))) | P14: =IF(AND($D14="Hito",P$5=$J14),"◆","") | Q14: =IF(AND($D14="Hito",Q$5=$J14),"◆","") | R14: =IF(AND($D14="Hito",R$5=$J14),"◆","") | S14: =IF(AND($D14="Hito",S$5=$J14),"◆","") | T14: =IF(AND($D14="Hito",T$5=$J14),"◆","") | U14: =IF(AND($D14="Hito",U$5=$J14),"◆","") | V14: =IF(AND($D14="Hito",V$5=$J14),"◆","") | W14: =IF(AND($D14="Hito",W$5=$J14),"◆","") | ... AU14: =IF(AND($D14="Hito",AU$5=$J14),"◆","") | AW14: 1 | AX14: =IF(AND(J14<=Hoy!$C$4,K14>=Hoy!$C$4),1,0) -> 1 | AY14: =IF(AX14=1,SUM($AX$6:AX14),"") -> 2 | AZ14: =IF(N14="Vencida",1,0) -> 0 | BA14: =IF(AZ14=1,SUM($AZ$6:AZ14),"")
A15: C09 | B15: 1. Pruebas y Validación Modelos de Negocios | C15: Validación de Modelos de Negocio y Facturación Electrónica | D15: Hito | E15: Modelos de negocio y documentos electrónicos (distribución, exportación, NC, ND) validados por el negocio y la DIAN. | F15: Negocio | G15: Jefe de Implementación | H15: Comercial / Facturación Colombia; Contabilidad Colombia; Logística / Bodega Colombia; TI Portland SD y FFEE | I15: Remoto | J15: 46325 | K15: 46325 | L15: =K15-J15+1 -> 1 | M15: No iniciado | N15: =IF(M15="Finalizado","",IF(K15<Hoy!$C$4,"Vencida",IF(AND(J15<=Hoy!$C$4,M15="No iniciado"),"Sin iniciar",""))) | P15: =IF(AND($D15="Hito",P$5=$J15),"◆","") | Q15: =IF(AND($D15="Hito",Q$5=$J15),"◆","") | R15: =IF(AND($D15="Hito",R$5=$J15),"◆","") | S15: =IF(AND($D15="Hito",S$5=$J15),"◆","") | T15: =IF(AND($D15="Hito",T$5=$J15),"◆","") | U15: =IF(AND($D15="Hito",U$5=$J15),"◆","") | V15: =IF(AND($D15="Hito",V$5=$J15),"◆","") | W15: =IF(AND($D15="Hito",W$5=$J15),"◆","") | ... AU15: =IF(AND($D15="Hito",AU$5=$J15),"◆","") | AW15: 1 | AX15: =IF(AND(J15<=Hoy!$C$4,K15>=Hoy!$C$4),1,0) -> 0 | AY15: =IF(AX15=1,SUM($AX$6:AX15),"") | AZ15: =IF(N15="Vencida",1,0) -> 0 | BA15: =IF(AZ15=1,SUM($AZ$6:AZ15),"")
A16: 2 | B16: 2. Datos maestros y Localización | C16: Datos maestros y Localización | D16: Fase | J16: =MIN(J17:J20) -> 46324 | K16: =MAX(K17:K20) -> 46328 | L16: =K16-J16+1 -> 5 | M16: =IF(COUNTIF(M17:M20,"Finalizado")=ROWS(M17:M20),"Finalizado",IF(OR(COUNTIF(M17:M20,"Demorado")>0,COUNTIF(N17:N20,"Vencida")>0),"Demorado",IF(COUNTIF(M17:M20,"En curso")+COUNTIF(M17:M20,"Finalizado")>0,"En curso","No iniciado"))) -> En curso | N16: =IF(COUNTIF(N17:N20,"Vencida")>0,COUNTIF(N17:N20,"Vencida")&" vencida(s)","") | O16: =COUNTIF(M17:M20,"Finalizado")&" de "&ROWS(M17:M20)&" finalizadas" -> 0 de 4 finalizadas | AW16: 0
A17: C10 | B17: 2. Datos maestros y Localización | C17: Plan de cuentas e impuestos validados en producción | D17: Actividad | E17: Cuentas, IVA, retenciones e ICA; se valida después del transporte 2. | F17: Financiero | G17: Gerente de Contabilidad Regional | H17: Contabilidad Colombia; TI Portland FICO; Implementador – Consultor FI/CO | I17: Remoto | J17: 46324 | K17: 46325 | L17: =K17-J17+1 -> 2 | M17: No iniciado | N17: =IF(M17="Finalizado","",IF(K17<Hoy!$C$4,"Vencida",IF(AND(J17<=Hoy!$C$4,M17="No iniciado"),"Sin iniciar",""))) | P17: =IF(AND($D17="Hito",P$5=$J17),"◆","") | Q17: =IF(AND($D17="Hito",Q$5=$J17),"◆","") | R17: =IF(AND($D17="Hito",R$5=$J17),"◆","") | S17: =IF(AND($D17="Hito",S$5=$J17),"◆","") | T17: =IF(AND($D17="Hito",T$5=$J17),"◆","") | U17: =IF(AND($D17="Hito",U$5=$J17),"◆","") | V17: =IF(AND($D17="Hito",V$5=$J17),"◆","") | W17: =IF(AND($D17="Hito",W$5=$J17),"◆","") | ... AU17: =IF(AND($D17="Hito",AU$5=$J17),"◆","") | AW17: 1 | AX17: =IF(AND(J17<=Hoy!$C$4,K17>=Hoy!$C$4),1,0) -> 0 | AY17: =IF(AX17=1,SUM($AX$6:AX17),"") | AZ17: =IF(N17="Vencida",1,0) -> 0 | BA17: =IF(AZ17=1,SUM($AZ$6:AZ17),"")
A18: C11 | B18: 2. Datos maestros y Localización | C18: Cierre de planillas de datos maestros del negocio | D18: Hito | E18: Planillas de clientes, proveedores y materiales entregadas a TI. | F18: Negocio | G18: Gerente de Contabilidad Regional | H18: Contabilidad Colombia; Comercial / Facturación Colombia; Logística / Bodega Colombia | I18: Remoto | J18: 46325 | K18: 46325 | L18: =K18-J18+1 -> 1 | M18: En curso | N18: =IF(M18="Finalizado","",IF(K18<Hoy!$C$4,"Vencida",IF(AND(J18<=Hoy!$C$4,M18="No iniciado"),"Sin iniciar",""))) | P18: =IF(AND($D18="Hito",P$5=$J18),"◆","") | Q18: =IF(AND($D18="Hito",Q$5=$J18),"◆","") | R18: =IF(AND($D18="Hito",R$5=$J18),"◆","") | S18: =IF(AND($D18="Hito",S$5=$J18),"◆","") | T18: =IF(AND($D18="Hito",T$5=$J18),"◆","") | U18: =IF(AND($D18="Hito",U$5=$J18),"◆","") | V18: =IF(AND($D18="Hito",V$5=$J18),"◆","") | W18: =IF(AND($D18="Hito",W$5=$J18),"◆","") | ... AU18: =IF(AND($D18="Hito",AU$5=$J18),"◆","") | AW18: 1 | AX18: =IF(AND(J18<=Hoy!$C$4,K18>=Hoy!$C$4),1,0) -> 0 | AY18: =IF(AX18=1,SUM($AX$6:AX18),"") | AZ18: =IF(N18="Vencida",1,0) -> 0 | BA18: =IF(AZ18=1,SUM($AZ$6:AZ18),"")
A19: C12 | B19: 2. Datos maestros y Localización | C19: Consolidación y formato de planillas por TI | D19: Actividad | E19: TI consolida y formatea las planillas en las plantillas de carga y las entrega a la Gerente de Contabilidad Regional. | F19: Técnico | G19: TI Portland MM | H19: TI Portland SD y FFEE; TI Portland FICO | I19: Remoto | J19: 46325 | K19: 46328 | L19: =K19-J19+1 -> 4 | M19: En curso | N19: =IF(M19="Finalizado","",IF(K19<Hoy!$C$4,"Vencida",IF(AND(J19<=Hoy!$C$4,M19="No iniciado"),"Sin iniciar",""))) | P19: =IF(AND($D19="Hito",P$5=$J19),"◆","") | Q19: =IF(AND($D19="Hito",Q$5=$J19),"◆","") | R19: =IF(AND($D19="Hito",R$5=$J19),"◆","") | S19: =IF(AND($D19="Hito",S$5=$J19),"◆","") | T19: =IF(AND($D19="Hito",T$5=$J19),"◆","") | U19: =IF(AND($D19="Hito",U$5=$J19),"◆","") | V19: =IF(AND($D19="Hito",V$5=$J19),"◆","") | W19: =IF(AND($D19="Hito",W$5=$J19),"◆","") | ... AU19: =IF(AND($D19="Hito",AU$5=$J19),"◆","") | AW19: 1 | AX19: =IF(AND(J19<=Hoy!$C$4,K19>=Hoy!$C$4),1,0) -> 0 | AY19: =IF(AX19=1,SUM($AX$6:AX19),"") | AZ19: =IF(N19="Vencida",1,0) -> 0 | BA19: =IF(AZ19=1,SUM($AZ$6:AZ19),"")
A20: C13 | B20: 2. Datos maestros y Localización | C20: Planillas de carga aprobadas | D20: Hito | E20: Revisión y aprobación de la Gerente de Contabilidad Regional. | F20: Financiero | G20: Gerente de Contabilidad Regional | H20: TI Portland FICO; TI Portland MM; TI Portland SD y FFEE | I20: Presencial | J20: 46328 | K20: 46328 | L20: =K20-J20+1 -> 1 | M20: No iniciado | N20: =IF(M20="Finalizado","",IF(K20<Hoy!$C$4,"Vencida",IF(AND(J20<=Hoy!$C$4,M20="No iniciado"),"Sin iniciar",""))) | P20: =IF(AND($D20="Hito",P$5=$J20),"◆","") | Q20: =IF(AND($D20="Hito",Q$5=$J20),"◆","") | R20: =IF(AND($D20="Hito",R$5=$J20),"◆","") | S20: =IF(AND($D20="Hito",S$5=$J20),"◆","") | T20: =IF(AND($D20="Hito",T$5=$J20),"◆","") | U20: =IF(AND($D20="Hito",U$5=$J20),"◆","") | V20: =IF(AND($D20="Hito",V$5=$J20),"◆","") | W20: =IF(AND($D20="Hito",W$5=$J20),"◆","") | ... AU20: =IF(AND($D20="Hito",AU$5=$J20),"◆","") | AW20: 1 | AX20: =IF(AND(J20<=Hoy!$C$4,K20>=Hoy!$C$4),1,0) -> 0 | AY20: =IF(AX20=1,SUM($AX$6:AX20),"") | AZ20: =IF(N20="Vencida",1,0) -> 0 | BA20: =IF(AZ20=1,SUM($AZ$6:AZ20),"")
A21: 3 | B21: 3. Cierre del sistema actual | C21: Cierre del sistema actual | D21: Fase | J21: =MIN(J22:J27) -> 46321 | K21: =MAX(K22:K27) -> 46330 | L21: =K21-J21+1 -> 10 | M21: =IF(COUNTIF(M22:M27,"Finalizado")=ROWS(M22:M27),"Finalizado",IF(OR(COUNTIF(M22:M27,"Demorado")>0,COUNTIF(N22:N27,"Vencida")>0),"Demorado",IF(COUNTIF(M22:M27,"En curso")+COUNTIF(M22:M27,"Finalizado")>0,"En curso","No iniciado"))) -> En curso | N21: =IF(COUNTIF(N22:N27,"Vencida")>0,COUNTIF(N22:N27,"Vencida")&" vencida(s)","") | O21: =COUNTIF(M22:M27,"Finalizado")&" de "&ROWS(M22:M27)&" finalizadas" -> 0 de 6 finalizadas | AW21: 0
A22: C14 | B22: 3. Cierre del sistema actual | C22: Registro de últimas operaciones en sistema actual | D22: Actividad | E22: Todas las transacciones de octubre ingresadas antes del corte. | F22: Negocio | G22: Contabilidad Colombia | H22: Comercial / Facturación Colombia; Logística / Bodega Colombia; Tesorería Colombia | I22: Remoto | J22: 46321 | K22: 46323 | L22: =K22-J22+1 -> 3 | M22: En curso | N22: =IF(M22="Finalizado","",IF(K22<Hoy!$C$4,"Vencida",IF(AND(J22<=Hoy!$C$4,M22="No iniciado"),"Sin iniciar",""))) | P22: =IF(AND($D22="Hito",P$5=$J22),"◆","") | Q22: =IF(AND($D22="Hito",Q$5=$J22),"◆","") | R22: =IF(AND($D22="Hito",R$5=$J22),"◆","") | S22: =IF(AND($D22="Hito",S$5=$J22),"◆","") | T22: =IF(AND($D22="Hito",T$5=$J22),"◆","") | U22: =IF(AND($D22="Hito",U$5=$J22),"◆","") | V22: =IF(AND($D22="Hito",V$5=$J22),"◆","") | W22: =IF(AND($D22="Hito",W$5=$J22),"◆","") | ... AU22: =IF(AND($D22="Hito",AU$5=$J22),"◆","") | AW22: 1 | AX22: =IF(AND(J22<=Hoy!$C$4,K22>=Hoy!$C$4),1,0) -> 1 | AY22: =IF(AX22=1,SUM($AX$6:AX22),"") -> 3 | AZ22: =IF(N22="Vencida",1,0) -> 0 | BA22: =IF(AZ22=1,SUM($AZ$6:AZ22),"")
A23: C15 | B23: 3. Cierre del sistema actual | C23: Cierre de registros del sistema actual | D23: Hito | E23: El sistema actual queda solo para consulta. | F23: Negocio | G23: Contabilidad Colombia | H23: Gerencia Colombia; PMO Portland | I23: Remoto | J23: 46323 | K23: 46323 | L23: =K23-J23+1 -> 1 | M23: En curso | N23: =IF(M23="Finalizado","",IF(K23<Hoy!$C$4,"Vencida",IF(AND(J23<=Hoy!$C$4,M23="No iniciado"),"Sin iniciar",""))) | P23: =IF(AND($D23="Hito",P$5=$J23),"◆","") | Q23: =IF(AND($D23="Hito",Q$5=$J23),"◆","") | R23: =IF(AND($D23="Hito",R$5=$J23),"◆","") | S23: =IF(AND($D23="Hito",S$5=$J23),"◆","") | T23: =IF(AND($D23="Hito",T$5=$J23),"◆","") | U23: =IF(AND($D23="Hito",U$5=$J23),"◆","") | V23: =IF(AND($D23="Hito",V$5=$J23),"◆","") | W23: =IF(AND($D23="Hito",W$5=$J23),"◆","") | ... AU23: =IF(AND($D23="Hito",AU$5=$J23),"◆","") | AW23: 1 | AX23: =IF(AND(J23<=Hoy!$C$4,K23>=Hoy!$C$4),1,0) -> 1 | AY23: =IF(AX23=1,SUM($AX$6:AX23),"") -> 4 | AZ23: =IF(N23="Vencida",1,0) -> 0 | BA23: =IF(AZ23=1,SUM($AZ$6:AZ23),"")
A24: C16 | B24: 3. Cierre del sistema actual | C24: Toma de inventario físico | D24: Actividad | E24: Conteo y reconteo de diferencias. | F24: Logístico | G24: Logística / Bodega Colombia | H24: Contabilidad Colombia; TI Portland MM | I24: Presencial | J24: 46324 | K24: 46329 | L24: =K24-J24+1 -> 6 | M24: No iniciado | N24: =IF(M24="Finalizado","",IF(K24<Hoy!$C$4,"Vencida",IF(AND(J24<=Hoy!$C$4,M24="No iniciado"),"Sin iniciar",""))) | P24: =IF(AND($D24="Hito",P$5=$J24),"◆","") | Q24: =IF(AND($D24="Hito",Q$5=$J24),"◆","") | R24: =IF(AND($D24="Hito",R$5=$J24),"◆","") | S24: =IF(AND($D24="Hito",S$5=$J24),"◆","") | T24: =IF(AND($D24="Hito",T$5=$J24),"◆","") | U24: =IF(AND($D24="Hito",U$5=$J24),"◆","") | V24: =IF(AND($D24="Hito",V$5=$J24),"◆","") | W24: =IF(AND($D24="Hito",W$5=$J24),"◆","") | ... AU24: =IF(AND($D24="Hito",AU$5=$J24),"◆","") | AW24: 1 | AX24: =IF(AND(J24<=Hoy!$C$4,K24>=Hoy!$C$4),1,0) -> 0 | AY24: =IF(AX24=1,SUM($AX$6:AX24),"") | AZ24: =IF(N24="Vencida",1,0) -> 0 | BA24: =IF(AZ24=1,SUM($AZ$6:AZ24),"")
A25: C17 | B25: 3. Cierre del sistema actual | C25: Valorización y conciliación del inventario | D25: Actividad | E25: Inventario contado valorizado y cuadrado contra contabilidad. | F25: Logístico | G25: Contabilidad Colombia | H25: Logística / Bodega Colombia; Gerente de Contabilidad Regional | I25: Presencial | J25: 46329 | K25: 46330 | L25: =K25-J25+1 -> 2 | M25: No iniciado | N25: =IF(M25="Finalizado","",IF(K25<Hoy!$C$4,"Vencida",IF(AND(J25<=Hoy!$C$4,M25="No iniciado"),"Sin iniciar",""))) | P25: =IF(AND($D25="Hito",P$5=$J25),"◆","") | Q25: =IF(AND($D25="Hito",Q$5=$J25),"◆","") | R25: =IF(AND($D25="Hito",R$5=$J25),"◆","") | S25: =IF(AND($D25="Hito",S$5=$J25),"◆","") | T25: =IF(AND($D25="Hito",T$5=$J25),"◆","") | U25: =IF(AND($D25="Hito",U$5=$J25),"◆","") | V25: =IF(AND($D25="Hito",V$5=$J25),"◆","") | W25: =IF(AND($D25="Hito",W$5=$J25),"◆","") | ... AU25: =IF(AND($D25="Hito",AU$5=$J25),"◆","") | AW25: 1 | AX25: =IF(AND(J25<=Hoy!$C$4,K25>=Hoy!$C$4),1,0) -> 0 | AY25: =IF(AX25=1,SUM($AX$6:AX25),"") | AZ25: =IF(N25="Vencida",1,0) -> 0 | BA25: =IF(AZ25=1,SUM($AZ$6:AZ25),"")
A26: C18 | B26: 3. Cierre del sistema actual | C26: Cierre contable de octubre con cuadratura de saldos | D26: Actividad | E26: Conciliaciones bancarias, impuestos y retenciones, clientes, proveedores, inventario y mayor cuadrados. | F26: Financiero | G26: Contabilidad Colombia | H26: Gerente de Contabilidad Regional; Tesorería Colombia | I26: Presencial | J26: 46324 | K26: 46330 | L26: =K26-J26+1 -> 7 | M26: No iniciado | N26: =IF(M26="Finalizado","",IF(K26<Hoy!$C$4,"Vencida",IF(AND(J26<=Hoy!$C$4,M26="No iniciado"),"Sin iniciar",""))) | P26: =IF(AND($D26="Hito",P$5=$J26),"◆","") | Q26: =IF(AND($D26="Hito",Q$5=$J26),"◆","") | R26: =IF(AND($D26="Hito",R$5=$J26),"◆","") | S26: =IF(AND($D26="Hito",S$5=$J26),"◆","") | T26: =IF(AND($D26="Hito",T$5=$J26),"◆","") | U26: =IF(AND($D26="Hito",U$5=$J26),"◆","") | V26: =IF(AND($D26="Hito",V$5=$J26),"◆","") | W26: =IF(AND($D26="Hito",W$5=$J26),"◆","") | ... AU26: =IF(AND($D26="Hito",AU$5=$J26),"◆","") | AW26: 1 | AX26: =IF(AND(J26<=Hoy!$C$4,K26>=Hoy!$C$4),1,0) -> 0 | AY26: =IF(AX26=1,SUM($AX$6:AX26),"") | AZ26: =IF(N26="Vencida",1,0) -> 0 | BA26: =IF(AZ26=1,SUM($AZ$6:AZ26),"")
A27: C19 | B27: 3. Cierre del sistema actual | C27: Cierre contable con saldos cuadrados | D27: Hito | E27: Balance de octubre aprobado: base para la carga de saldos. | F27: Financiero | G27: Gerente de Contabilidad Regional | H27: Contabilidad Colombia; Gerencia Colombia | I27: Presencial | J27: 46330 | K27: 46330 | L27: =K27-J27+1 -> 1 | M27: No iniciado | N27: =IF(M27="Finalizado","",IF(K27<Hoy!$C$4,"Vencida",IF(AND(J27<=Hoy!$C$4,M27="No iniciado"),"Sin iniciar",""))) | P27: =IF(AND($D27="Hito",P$5=$J27),"◆","") | Q27: =IF(AND($D27="Hito",Q$5=$J27),"◆","") | R27: =IF(AND($D27="Hito",R$5=$J27),"◆","") | S27: =IF(AND($D27="Hito",S$5=$J27),"◆","") | T27: =IF(AND($D27="Hito",T$5=$J27),"◆","") | U27: =IF(AND($D27="Hito",U$5=$J27),"◆","") | V27: =IF(AND($D27="Hito",V$5=$J27),"◆","") | W27: =IF(AND($D27="Hito",W$5=$J27),"◆","") | ... AU27: =IF(AND($D27="Hito",AU$5=$J27),"◆","") | AW27: 1 | AX27: =IF(AND(J27<=Hoy!$C$4,K27>=Hoy!$C$4),1,0) -> 0 | AY27: =IF(AX27=1,SUM($AX$6:AX27),"") | AZ27: =IF(N27="Vencida",1,0) -> 0 | BA27: =IF(AZ27=1,SUM($AZ$6:AZ27),"")
A28: 4 | B28: 4. Operación en contingencia | C28: Operación en contingencia | D28: Fase | J28: =MIN(J29:J31) -> 46329 | K28: =MAX(K29:K31) -> 46332 | L28: =K28-J28+1 -> 4 | M28: =IF(COUNTIF(M29:M31,"Finalizado")=ROWS(M29:M31),"Finalizado",IF(OR(COUNTIF(M29:M31,"Demorado")>0,COUNTIF(N29:N31,"Vencida")>0),"Demorado",IF(COUNTIF(M29:M31,"En curso")+COUNTIF(M29:M31,"Finalizado")>0,"En curso","No iniciado"))) -> No iniciado | N28: =IF(COUNTIF(N29:N31,"Vencida")>0,COUNTIF(N29:N31,"Vencida")&" vencida(s)","") | O28: =COUNTIF(M29:M31,"Finalizado")&" de "&ROWS(M29:M31)&" finalizadas" -> 0 de 3 finalizadas | AW28: 0
A29: C20 | B29: 4. Operación en contingencia | C29: Ventas con facturas manuales | D29: Actividad | E29: Emisión controlada según procedimiento de contingencia. | F29: Negocio | G29: Comercial / Facturación Colombia | H29: TI Portland SD y FFEE; Proveedor FE (Estupendo) | I29: Presencial | J29: 46329 | K29: 46332 | L29: =K29-J29+1 -> 4 | M29: No iniciado | N29: =IF(M29="Finalizado","",IF(K29<Hoy!$C$4,"Vencida",IF(AND(J29<=Hoy!$C$4,M29="No iniciado"),"Sin iniciar",""))) | P29: =IF(AND($D29="Hito",P$5=$J29),"◆","") | Q29: =IF(AND($D29="Hito",Q$5=$J29),"◆","") | R29: =IF(AND($D29="Hito",R$5=$J29),"◆","") | S29: =IF(AND($D29="Hito",S$5=$J29),"◆","") | T29: =IF(AND($D29="Hito",T$5=$J29),"◆","") | U29: =IF(AND($D29="Hito",U$5=$J29),"◆","") | V29: =IF(AND($D29="Hito",V$5=$J29),"◆","") | W29: =IF(AND($D29="Hito",W$5=$J29),"◆","") | ... AU29: =IF(AND($D29="Hito",AU$5=$J29),"◆","") | AW29: 1 | AX29: =IF(AND(J29<=Hoy!$C$4,K29>=Hoy!$C$4),1,0) -> 0 | AY29: =IF(AX29=1,SUM($AX$6:AX29),"") | AZ29: =IF(N29="Vencida",1,0) -> 0 | BA29: =IF(AZ29=1,SUM($AZ$6:AZ29),"")
A30: C21 | B30: 4. Operación en contingencia | C30: Compras y recepciones manuales | D30: Actividad | E30: Registro en planilla de pedidos y recepciones. | F30: Logístico | G30: Logística / Bodega Colombia | H30: TI Portland MM | I30: Presencial | J30: 46329 | K30: 46332 | L30: =K30-J30+1 -> 4 | M30: No iniciado | N30: =IF(M30="Finalizado","",IF(K30<Hoy!$C$4,"Vencida",IF(AND(J30<=Hoy!$C$4,M30="No iniciado"),"Sin iniciar",""))) | P30: =IF(AND($D30="Hito",P$5=$J30),"◆","") | Q30: =IF(AND($D30="Hito",Q$5=$J30),"◆","") | R30: =IF(AND($D30="Hito",R$5=$J30),"◆","") | S30: =IF(AND($D30="Hito",S$5=$J30),"◆","") | T30: =IF(AND($D30="Hito",T$5=$J30),"◆","") | U30: =IF(AND($D30="Hito",U$5=$J30),"◆","") | V30: =IF(AND($D30="Hito",V$5=$J30),"◆","") | W30: =IF(AND($D30="Hito",W$5=$J30),"◆","") | ... AU30: =IF(AND($D30="Hito",AU$5=$J30),"◆","") | AW30: 1 | AX30: =IF(AND(J30<=Hoy!$C$4,K30>=Hoy!$C$4),1,0) -> 0 | AY30: =IF(AX30=1,SUM($AX$6:AX30),"") | AZ30: =IF(N30="Vencida",1,0) -> 0 | BA30: =IF(AZ30=1,SUM($AZ$6:AZ30),"")
A31: C22 | B31: 4. Operación en contingencia | C31: Cobros y pagos manuales | D31: Actividad | E31: Registro en planilla de movimientos bancarios. | F31: Financiero | G31: Tesorería Colombia | H31: Contabilidad Colombia | I31: Presencial | J31: 46329 | K31: 46332 | L31: =K31-J31+1 -> 4 | M31: No iniciado | N31: =IF(M31="Finalizado","",IF(K31<Hoy!$C$4,"Vencida",IF(AND(J31<=Hoy!$C$4,M31="No iniciado"),"Sin iniciar",""))) | P31: =IF(AND($D31="Hito",P$5=$J31),"◆","") | Q31: =IF(AND($D31="Hito",Q$5=$J31),"◆","") | R31: =IF(AND($D31="Hito",R$5=$J31),"◆","") | S31: =IF(AND($D31="Hito",S$5=$J31),"◆","") | T31: =IF(AND($D31="Hito",T$5=$J31),"◆","") | U31: =IF(AND($D31="Hito",U$5=$J31),"◆","") | V31: =IF(AND($D31="Hito",V$5=$J31),"◆","") | W31: =IF(AND($D31="Hito",W$5=$J31),"◆","") | ... AU31: =IF(AND($D31="Hito",AU$5=$J31),"◆","") | AW31: 1 | AX31: =IF(AND(J31<=Hoy!$C$4,K31>=Hoy!$C$4),1,0) -> 0 | AY31: =IF(AX31=1,SUM($AX$6:AX31),"") | AZ31: =IF(N31="Vencida",1,0) -> 0 | BA31: =IF(AZ31=1,SUM($AZ$6:AZ31),"")
A32: 5 | B32: 5. Secuencia de Paso a Producción | C32: Secuencia de Paso a Producción | D32: Fase | J32: =MIN(J33:J40) -> 46321 | K32: =MAX(K33:K40) -> 46330 | L32: =K32-J32+1 -> 10 | M32: =IF(COUNTIF(M33:M40,"Finalizado")=ROWS(M33:M40),"Finalizado",IF(OR(COUNTIF(M33:M40,"Demorado")>0,COUNTIF(N33:N40,"Vencida")>0),"Demorado",IF(COUNTIF(M33:M40,"En curso")+COUNTIF(M33:M40,"Finalizado")>0,"En curso","No iniciado"))) -> En curso | N32: =IF(COUNTIF(N33:N40,"Vencida")>0,COUNTIF(N33:N40,"Vencida")&" vencida(s)","") | O32: =COUNTIF(M33:M40,"Finalizado")&" de "&ROWS(M33:M40)&" finalizadas" -> 0 de 8 finalizadas | AW32: 0
A33: C23 | B33: 5. Secuencia de Paso a Producción | C33: Pruebas de Regresión Perú | D33: Actividad | E33: Ejecución de Flujos de Compra, Venta y Facturación en la sociedad 2000 para validar que no hay impacto en lo existente. | F33: Negocio | G33: TI Portland Perú | H33: TI Portland Perú | I33: Remoto | J33: 46321 | K33: 46323 | L33: =K33-J33+1 -> 3 | M33: En curso | N33: =IF(M33="Finalizado","",IF(K33<Hoy!$C$4,"Vencida",IF(AND(J33<=Hoy!$C$4,M33="No iniciado"),"Sin iniciar",""))) | P33: =IF(AND($D33="Hito",P$5=$J33),"◆","") | Q33: =IF(AND($D33="Hito",Q$5=$J33),"◆","") | R33: =IF(AND($D33="Hito",R$5=$J33),"◆","") | S33: =IF(AND($D33="Hito",S$5=$J33),"◆","") | T33: =IF(AND($D33="Hito",T$5=$J33),"◆","") | U33: =IF(AND($D33="Hito",U$5=$J33),"◆","") | V33: =IF(AND($D33="Hito",V$5=$J33),"◆","") | W33: =IF(AND($D33="Hito",W$5=$J33),"◆","") | ... AU33: =IF(AND($D33="Hito",AU$5=$J33),"◆","") | AW33: 1 | AX33: =IF(AND(J33<=Hoy!$C$4,K33>=Hoy!$C$4),1,0) -> 1 | AY33: =IF(AX33=1,SUM($AX$6:AX33),"") -> 5 | AZ33: =IF(N33="Vencida",1,0) -> 0 | BA33: =IF(AZ33=1,SUM($AZ$6:AZ33),"")
A34: C24 | B34: 5. Secuencia de Paso a Producción | C34: Paso a producción 1: estructuras organizativas y configuraciones base | D34: Actividad | E34: Sociedad, centros, almacenes, organizaciones de compra y venta y parametrización base. | F34: Técnico | G34: Jefe de Implementación | H34: Implementador – Consultor FI/CO; Implementador – Consultor MM/SD; Implementador – FFEE/Formularios; TI Portland FICO | I34: Remoto | J34: 46324 | K34: 46325 | L34: =K34-J34+1 -> 2 | M34: No iniciado | N34: =IF(M34="Finalizado","",IF(K34<Hoy!$C$4,"Vencida",IF(AND(J34<=Hoy!$C$4,M34="No iniciado"),"Sin iniciar",""))) | P34: =IF(AND($D34="Hito",P$5=$J34),"◆","") | Q34: =IF(AND($D34="Hito",Q$5=$J34),"◆","") | R34: =IF(AND($D34="Hito",R$5=$J34),"◆","") | S34: =IF(AND($D34="Hito",S$5=$J34),"◆","") | T34: =IF(AND($D34="Hito",T$5=$J34),"◆","") | U34: =IF(AND($D34="Hito",U$5=$J34),"◆","") | V34: =IF(AND($D34="Hito",V$5=$J34),"◆","") | W34: =IF(AND($D34="Hito",W$5=$J34),"◆","") | ... AU34: =IF(AND($D34="Hito",AU$5=$J34),"◆","") | AW34: 1 | AX34: =IF(AND(J34<=Hoy!$C$4,K34>=Hoy!$C$4),1,0) -> 0 | AY34: =IF(AX34=1,SUM($AX$6:AX34),"") | AZ34: =IF(N34="Vencida",1,0) -> 0 | BA34: =IF(AZ34=1,SUM($AZ$6:AZ34),"")
A35: C25 | B35: 5. Secuencia de Paso a Producción | C35: Paso a producción 2: plan de cuentas | D35: Actividad | E35: Plan de cuentas, determinación de cuentas e impuestos. | F35: Técnico | G35: Jefe de Implementación | H35: Implementador – Consultor FI/CO; Implementador – Consultor MM/SD; Implementador – FFEE/Formularios; TI Portland FICO | I35: Remoto | J35: 46324 | K35: 46325 | L35: =K35-J35+1 -> 2 | M35: No iniciado | N35: =IF(M35="Finalizado","",IF(K35<Hoy!$C$4,"Vencida",IF(AND(J35<=Hoy!$C$4,M35="No iniciado"),"Sin iniciar",""))) | P35: =IF(AND($D35="Hito",P$5=$J35),"◆","") | Q35: =IF(AND($D35="Hito",Q$5=$J35),"◆","") | R35: =IF(AND($D35="Hito",R$5=$J35),"◆","") | S35: =IF(AND($D35="Hito",S$5=$J35),"◆","") | T35: =IF(AND($D35="Hito",T$5=$J35),"◆","") | U35: =IF(AND($D35="Hito",U$5=$J35),"◆","") | V35: =IF(AND($D35="Hito",V$5=$J35),"◆","") | W35: =IF(AND($D35="Hito",W$5=$J35),"◆","") | ... AU35: =IF(AND($D35="Hito",AU$5=$J35),"◆","") | AW35: 1 | AX35: =IF(AND(J35<=Hoy!$C$4,K35>=Hoy!$C$4),1,0) -> 0 | AY35: =IF(AX35=1,SUM($AX$6:AX35),"") | AZ35: =IF(N35="Vencida",1,0) -> 0 | BA35: =IF(AZ35=1,SUM($AZ$6:AZ35),"")
A36: C26 | B36: 5. Secuencia de Paso a Producción | C36: Paso a producción 3: centros de costos | D36: Actividad | E36: Jerarquía estándar y centros de costo / beneficio. | F36: Técnico | G36: Jefe de Implementación | H36: Implementador – Consultor FI/CO; Implementador – Consultor MM/SD; Implementador – FFEE/Formularios; TI Portland FICO | I36: Remoto | J36: 46324 | K36: 46325 | L36: =K36-J36+1 -> 2 | M36: No iniciado | N36: =IF(M36="Finalizado","",IF(K36<Hoy!$C$4,"Vencida",IF(AND(J36<=Hoy!$C$4,M36="No iniciado"),"Sin iniciar",""))) | P36: =IF(AND($D36="Hito",P$5=$J36),"◆","") | Q36: =IF(AND($D36="Hito",Q$5=$J36),"◆","") | R36: =IF(AND($D36="Hito",R$5=$J36),"◆","") | S36: =IF(AND($D36="Hito",S$5=$J36),"◆","") | T36: =IF(AND($D36="Hito",T$5=$J36),"◆","") | U36: =IF(AND($D36="Hito",U$5=$J36),"◆","") | V36: =IF(AND($D36="Hito",V$5=$J36),"◆","") | W36: =IF(AND($D36="Hito",W$5=$J36),"◆","") | ... AU36: =IF(AND($D36="Hito",AU$5=$J36),"◆","") | AW36: 1 | AX36: =IF(AND(J36<=Hoy!$C$4,K36>=Hoy!$C$4),1,0) -> 0 | AY36: =IF(AX36=1,SUM($AX$6:AX36),"") | AZ36: =IF(N36="Vencida",1,0) -> 0 | BA36: =IF(AZ36=1,SUM($AZ$6:AZ36),"")
A37: C27 | B37: 5. Secuencia de Paso a Producción | C37: Paso a producción 4: modelos de negocio y Facturación Electrónica | D37: Actividad | E37: Procesos de compra, venta y formularios; habilitación productiva de FE con Estupendo y DIAN. | F37: Técnico | G37: Jefe de Implementación | H37: Implementador – Consultor FI/CO; Implementador – Consultor MM/SD; Implementador – FFEE/Formularios; TI Portland FICO; TI Portland SD y FFEE; Proveedor FE (Estupendo) | I37: Remoto | J37: 46324 | K37: 46325 | L37: =K37-J37+1 -> 2 | M37: No iniciado | N37: =IF(M37="Finalizado","",IF(K37<Hoy!$C$4,"Vencida",IF(AND(J37<=Hoy!$C$4,M37="No iniciado"),"Sin iniciar",""))) | P37: =IF(AND($D37="Hito",P$5=$J37),"◆","") | Q37: =IF(AND($D37="Hito",Q$5=$J37),"◆","") | R37: =IF(AND($D37="Hito",R$5=$J37),"◆","") | S37: =IF(AND($D37="Hito",S$5=$J37),"◆","") | T37: =IF(AND($D37="Hito",T$5=$J37),"◆","") | U37: =IF(AND($D37="Hito",U$5=$J37),"◆","") | V37: =IF(AND($D37="Hito",V$5=$J37),"◆","") | W37: =IF(AND($D37="Hito",W$5=$J37),"◆","") | ... AU37: =IF(AND($D37="Hito",AU$5=$J37),"◆","") | AW37: 1 | AX37: =IF(AND(J37<=Hoy!$C$4,K37>=Hoy!$C$4),1,0) -> 0 | AY37: =IF(AX37=1,SUM($AX$6:AX37),"") | AZ37: =IF(N37="Vencida",1,0) -> 0 | BA37: =IF(AZ37=1,SUM($AZ$6:AZ37),"")
A38: C28 | B38: 5. Secuencia de Paso a Producción | C38: Paso a producción 5: carga de datos maestros | D38: Actividad | E38: Clientes, proveedores, materiales y activos fijos; antes de la carga de saldos. Preparación y ejecución: Sebastián Salom (externo). | F38: Financiero | G38: Gerente de Contabilidad Regional | H38: Externo – Migración; TI Portland FICO; TI Portland MM; TI Portland SD y FFEE; Implementador – Consultor FI/CO; Implementador – Consultor MM/SD | I38: Presencial | J38: 46329 | K38: 46330 | L38: =K38-J38+1 -> 2 | M38: No iniciado | N38: =IF(M38="Finalizado","",IF(K38<Hoy!$C$4,"Vencida",IF(AND(J38<=Hoy!$C$4,M38="No iniciado"),"Sin iniciar",""))) | P38: =IF(AND($D38="Hito",P$5=$J38),"◆","") | Q38: =IF(AND($D38="Hito",Q$5=$J38),"◆","") | R38: =IF(AND($D38="Hito",R$5=$J38),"◆","") | S38: =IF(AND($D38="Hito",S$5=$J38),"◆","") | T38: =IF(AND($D38="Hito",T$5=$J38),"◆","") | U38: =IF(AND($D38="Hito",U$5=$J38),"◆","") | V38: =IF(AND($D38="Hito",V$5=$J38),"◆","") | W38: =IF(AND($D38="Hito",W$5=$J38),"◆","") | ... AU38: =IF(AND($D38="Hito",AU$5=$J38),"◆","") | AW38: 1 | AX38: =IF(AND(J38<=Hoy!$C$4,K38>=Hoy!$C$4),1,0) -> 0 | AY38: =IF(AX38=1,SUM($AX$6:AX38),"") | AZ38: =IF(N38="Vencida",1,0) -> 0 | BA38: =IF(AZ38=1,SUM($AZ$6:AZ38),"")
A39: C29 | B39: 5. Secuencia de Paso a Producción | C39: Validación y Ajustes | D39: Actividad | E39: Revisión de las estructuras y datos cargados y aplicación de ajustes requeridos (delta) | F39: Técnico | G39: Jefe de Implementación | H39: Implementador – Consultor FI/CO; Implementador – Consultor MM/SD; Implementador – FFEE/Formularios; TI Portland FICO; TI Portland SD y FFEE; Proveedor FE (Estupendo) | I39: Remoto | J39: 46329 | K39: 46330 | L39: =K39-J39+1 -> 2 | M39: No iniciado | N39: =IF(M39="Finalizado","",IF(K39<Hoy!$C$4,"Vencida",IF(AND(J39<=Hoy!$C$4,M39="No iniciado"),"Sin iniciar",""))) | P39: =IF(AND($D39="Hito",P$5=$J39),"◆","") | Q39: =IF(AND($D39="Hito",Q$5=$J39),"◆","") | R39: =IF(AND($D39="Hito",R$5=$J39),"◆","") | S39: =IF(AND($D39="Hito",S$5=$J39),"◆","") | T39: =IF(AND($D39="Hito",T$5=$J39),"◆","") | U39: =IF(AND($D39="Hito",U$5=$J39),"◆","") | V39: =IF(AND($D39="Hito",V$5=$J39),"◆","") | W39: =IF(AND($D39="Hito",W$5=$J39),"◆","") | ... AU39: =IF(AND($D39="Hito",AU$5=$J39),"◆","") | AW39: 1 | AX39: =IF(AND(J39<=Hoy!$C$4,K39>=Hoy!$C$4),1,0) -> 0 | AY39: =IF(AX39=1,SUM($AX$6:AX39),"") | AZ39: =IF(N39="Vencida",1,0) -> 0 | BA39: =IF(AZ39=1,SUM($AZ$6:AZ39),"")
A40: C30 | B40: 5. Secuencia de Paso a Producción | C40: Datos maestros cargados y validados | D40: Hito | E40: Conformidad sobre muestra de registros cargados. Preparación y ejecución: Sebastián Salom (externo). | F40: Financiero | G40: Gerente de Contabilidad Regional | H40: Externo – Migración; Contabilidad Colombia; Comercial / Facturación Colombia; Logística / Bodega Colombia | I40: Presencial | J40: 46330 | K40: 46330 | L40: =K40-J40+1 -> 1 | M40: No iniciado | N40: =IF(M40="Finalizado","",IF(K40<Hoy!$C$4,"Vencida",IF(AND(J40<=Hoy!$C$4,M40="No iniciado"),"Sin iniciar",""))) | P40: =IF(AND($D40="Hito",P$5=$J40),"◆","") | Q40: =IF(AND($D40="Hito",Q$5=$J40),"◆","") | R40: =IF(AND($D40="Hito",R$5=$J40),"◆","") | S40: =IF(AND($D40="Hito",S$5=$J40),"◆","") | T40: =IF(AND($D40="Hito",T$5=$J40),"◆","") | U40: =IF(AND($D40="Hito",U$5=$J40),"◆","") | V40: =IF(AND($D40="Hito",V$5=$J40),"◆","") | W40: =IF(AND($D40="Hito",W$5=$J40),"◆","") | ... AU40: =IF(AND($D40="Hito",AU$5=$J40),"◆","") | AW40: 1 | AX40: =IF(AND(J40<=Hoy!$C$4,K40>=Hoy!$C$4),1,0) -> 0 | AY40: =IF(AX40=1,SUM($AX$6:AX40),"") | AZ40: =IF(N40="Vencida",1,0) -> 0 | BA40: =IF(AZ40=1,SUM($AZ$6:AZ40),"")
...

Sheet Resumen
A1: Estatus resumido del cutover
A2: Se calcula desde la hoja Gantt Cutover y la fecha de la hoja Hoy.
B3: ="Fecha de consulta: "&TEXT(Hoy!$C$4,"dd-mm-yyyy")&" · Go-Live: "&TEXT('Equipo y Calendario'!$B$28,"dd-mm-yyyy") -> Fecha de consulta: 28-10-2026 · Go-Live: 09-11-2026
B5: Actividades e hitos | C5: Finalizadas | D5: En curso | E5: Demoradas | F5: No iniciadas | G5: Vencidas | H5: % finalizado | I5: Días al Go-Live
B6: =COUNTIFS('Gantt Cutover'!$D$6:$D$63,"<>Fase") -> 48 | C6: =COUNTIFS('Gantt Cutover'!$D$6:$D$63,"<>Fase",'Gantt Cutover'!$M$6:$M$63,"Finalizado") -> 0 | D6: =COUNTIFS('Gantt Cutover'!$D$6:$D$63,"<>Fase",'Gantt Cutover'!$M$6:$M$63,"En curso") -> 7 | E6: =COUNTIFS('Gantt Cutover'!$D$6:$D$63,"<>Fase",'Gantt Cutover'!$M$6:$M$63,"Demorado") -> 0 | F6: =COUNTIFS('Gantt Cutover'!$D$6:$D$63,"<>Fase",'Gantt Cutover'!$M$6:$M$63,"No iniciado") -> 41 | G6: =COUNTIF('Gantt Cutover'!$N$6:$N$63,"Vencida") -> 0 | H6: =IFERROR(C6/B6,0) -> 0 | I6: ='Equipo y Calendario'!$B$28-Hoy!$C$4 -> 12
B8: Avance por fase
B9: Fase | C9: Inicio | D9: Fin | E9: Total | F9: No iniciado | G9: En curso | H9: Demorado | I9: Finalizado | J9: % finalizado | K9: Vencidas | L9: Estado de la fase
B10: 0. Equipo de proyecto en Colombia | C10: ='Gantt Cutover'!J6 -> 46328 | D10: ='Gantt Cutover'!K6 -> 46346 | E10: =COUNTIFS('Gantt Cutover'!$B$6:$B$63,$B10,'Gantt Cutover'!$D$6:$D$63,"<>Fase") -> 5 | F10: =COUNTIFS('Gantt Cutover'!$B$6:$B$63,$B10,'Gantt Cutover'!$D$6:$D$63,"<>Fase",'Gantt Cutover'!$M$6:$M$63,"No iniciado") -> 5 | G10: =COUNTIFS('Gantt Cutover'!$B$6:$B$63,$B10,'Gantt Cutover'!$D$6:$D$63,"<>Fase",'Gantt Cutover'!$M$6:$M$63,"En curso") -> 0 | H10: =COUNTIFS('Gantt Cutover'!$B$6:$B$63,$B10,'Gantt Cutover'!$D$6:$D$63,"<>Fase",'Gantt Cutover'!$M$6:$M$63,"Demorado") -> 0 | I10: =COUNTIFS('Gantt Cutover'!$B$6:$B$63,$B10,'Gantt Cutover'!$D$6:$D$63,"<>Fase",'Gantt Cutover'!$M$6:$M$63,"Finalizado") -> 0 | J10: =IFERROR(I10/E10,0) -> 0 | K10: =COUNTIFS('Gantt Cutover'!$B$6:$B$63,$B10,'Gantt Cutover'!$N$6:$N$63,"Vencida") -> 0 | L10: ='Gantt Cutover'!M6 -> No iniciado
B11: 1. Pruebas y Validación Modelos de Negocios | C11: ='Gantt Cutover'!J12 -> 46321 | D11: ='Gantt Cutover'!K12 -> 46325 | E11: =COUNTIFS('Gantt Cutover'!$B$6:$B$63,$B11,'Gantt Cutover'!$D$6:$D$63,"<>Fase") -> 3 | F11: =COUNTIFS('Gantt Cutover'!$B$6:$B$63,$B11,'Gantt Cutover'!$D$6:$D$63,"<>Fase",'Gantt Cutover'!$M$6:$M$63,"No iniciado") -> 1 | G11: =COUNTIFS('Gantt Cutover'!$B$6:$B$63,$B11,'Gantt Cutover'!$D$6:$D$63,"<>Fase",'Gantt Cutover'!$M$6:$M$63,"En curso") -> 2 | H11: =COUNTIFS('Gantt Cutover'!$B$6:$B$63,$B11,'Gantt Cutover'!$D$6:$D$63,"<>Fase",'Gantt Cutover'!$M$6:$M$63,"Demorado") -> 0 | I11: =COUNTIFS('Gantt Cutover'!$B$6:$B$63,$B11,'Gantt Cutover'!$D$6:$D$63,"<>Fase",'Gantt Cutover'!$M$6:$M$63,"Finalizado") -> 0 | J11: =IFERROR(I11/E11,0) -> 0 | K11: =COUNTIFS('Gantt Cutover'!$B$6:$B$63,$B11,'Gantt Cutover'!$N$6:$N$63,"Vencida") -> 0 | L11: ='Gantt Cutover'!M12 -> En curso
B12: 2. Datos maestros y Localización | C12: ='Gantt Cutover'!J16 -> 46324 | D12: ='Gantt Cutover'!K16 -> 46328 | E12: =COUNTIFS('Gantt Cutover'!$B$6:$B$63,$B12,'Gantt Cutover'!$D$6:$D$63,"<>Fase") -> 4 | F12: =COUNTIFS('Gantt Cutover'!$B$6:$B$63,$B12,'Gantt Cutover'!$D$6:$D$63,"<>Fase",'Gantt Cutover'!$M$6:$M$63,"No iniciado") -> 2 | G12: =COUNTIFS('Gantt Cutover'!$B$6:$B$63,$B12,'Gantt Cutover'!$D$6:$D$63,"<>Fase",'Gantt Cutover'!$M$6:$M$63,"En curso") -> 2 | H12: =COUNTIFS('Gantt Cutover'!$B$6:$B$63,$B12,'Gantt Cutover'!$D$6:$D$63,"<>Fase",'Gantt Cutover'!$M$6:$M$63,"Demorado") -> 0 | I12: =COUNTIFS('Gantt Cutover'!$B$6:$B$63,$B12,'Gantt Cutover'!$D$6:$D$63,"<>Fase",'Gantt Cutover'!$M$6:$M$63,"Finalizado") -> 0 | J12: =IFERROR(I12/E12,0) -> 0 | K12: =COUNTIFS('Gantt Cutover'!$B$6:$B$63,$B12,'Gantt Cutover'!$N$6:$N$63,"Vencida") -> 0 | L12: ='Gantt Cutover'!M16 -> En curso
B13: 3. Cierre del sistema actual | C13: ='Gantt Cutover'!J21 -> 46321 | D13: ='Gantt Cutover'!K21 -> 46330 | E13: =COUNTIFS('Gantt Cutover'!$B$6:$B$63,$B13,'Gantt Cutover'!$D$6:$D$63,"<>Fase") -> 6 | F13: =COUNTIFS('Gantt Cutover'!$B$6:$B$63,$B13,'Gantt Cutover'!$D$6:$D$63,"<>Fase",'Gantt Cutover'!$M$6:$M$63,"No iniciado") -> 4 | G13: =COUNTIFS('Gantt Cutover'!$B$6:$B$63,$B13,'Gantt Cutover'!$D$6:$D$63,"<>Fase",'Gantt Cutover'!$M$6:$M$63,"En curso") -> 2 | H13: =COUNTIFS('Gantt Cutover'!$B$6:$B$63,$B13,'Gantt Cutover'!$D$6:$D$63,"<>Fase",'Gantt Cutover'!$M$6:$M$63,"Demorado") -> 0 | I13: =COUNTIFS('Gantt Cutover'!$B$6:$B$63,$B13,'Gantt Cutover'!$D$6:$D$63,"<>Fase",'Gantt Cutover'!$M$6:$M$63,"Finalizado") -> 0 | J13: =IFERROR(I13/E13,0) -> 0 | K13: =COUNTIFS('Gantt Cutover'!$B$6:$B$63,$B13,'Gantt Cutover'!$N$6:$N$63,"Vencida") -> 0 | L13: ='Gantt Cutover'!M21 -> En curso
B14: 4. Operación en contingencia | C14: ='Gantt Cutover'!J28 -> 46329 | D14: ='Gantt Cutover'!K28 -> 46332 | E14: =COUNTIFS('Gantt Cutover'!$B$6:$B$63,$B14,'Gantt Cutover'!$D$6:$D$63,"<>Fase") -> 3 | F14: =COUNTIFS('Gantt Cutover'!$B$6:$B$63,$B14,'Gantt Cutover'!$D$6:$D$63,"<>Fase",'Gantt Cutover'!$M$6:$M$63,"No iniciado") -> 3 | G14: =COUNTIFS('Gantt Cutover'!$B$6:$B$63,$B14,'Gantt Cutover'!$D$6:$D$63,"<>Fase",'Gantt Cutover'!$M$6:$M$63,"En curso") -> 0 | H14: =COUNTIFS('Gantt Cutover'!$B$6:$B$63,$B14,'Gantt Cutover'!$D$6:$D$63,"<>Fase",'Gantt Cutover'!$M$6:$M$63,"Demorado") -> 0 | I14: =COUNTIFS('Gantt Cutover'!$B$6:$B$63,$B14,'Gantt Cutover'!$D$6:$D$63,"<>Fase",'Gantt Cutover'!$M$6:$M$63,"Finalizado") -> 0 | J14: =IFERROR(I14/E14,0) -> 0 | K14: =COUNTIFS('Gantt Cutover'!$B$6:$B$63,$B14,'Gantt Cutover'!$N$6:$N$63,"Vencida") -> 0 | L14: ='Gantt Cutover'!M28 -> No iniciado
B15: 5. Secuencia de Paso a Producción | C15: ='Gantt Cutover'!J32 -> 46321 | D15: ='Gantt Cutover'!K32 -> 46330 | E15: =COUNTIFS('Gantt Cutover'!$B$6:$B$63,$B15,'Gantt Cutover'!$D$6:$D$63,"<>Fase") -> 8 | F15: =COUNTIFS('Gantt Cutover'!$B$6:$B$63,$B15,'Gantt Cutover'!$D$6:$D$63,"<>Fase",'Gantt Cutover'!$M$6:$M$63,"No iniciado") -> 7 | G15: =COUNTIFS('Gantt Cutover'!$B$6:$B$63,$B15,'Gantt Cutover'!$D$6:$D$63,"<>Fase",'Gantt Cutover'!$M$6:$M$63,"En curso") -> 1 | H15: =COUNTIFS('Gantt Cutover'!$B$6:$B$63,$B15,'Gantt Cutover'!$D$6:$D$63,"<>Fase",'Gantt Cutover'!$M$6:$M$63,"Demorado") -> 0 | I15: =COUNTIFS('Gantt Cutover'!$B$6:$B$63,$B15,'Gantt Cutover'!$D$6:$D$63,"<>Fase",'Gantt Cutover'!$M$6:$M$63,"Finalizado") -> 0 | J15: =IFERROR(I15/E15,0) -> 0 | K15: =COUNTIFS('Gantt Cutover'!$B$6:$B$63,$B15,'Gantt Cutover'!$N$6:$N$63,"Vencida") -> 0 | L15: ='Gantt Cutover'!M32 -> En curso
B16: 6. Carga de Saldos Iniciales | C16: ='Gantt Cutover'!J41 -> 46330 | D16: ='Gantt Cutover'!K41 -> 46332 | E16: =COUNTIFS('Gantt Cutover'!$B$6:$B$63,$B16,'Gantt Cutover'!$D$6:$D$63,"<>Fase") -> 6 | F16: =COUNTIFS('Gantt Cutover'!$B$6:$B$63,$B16,'Gantt Cutover'!$D$6:$D$63,"<>Fase",'Gantt Cutover'!$M$6:$M$63,"No iniciado") -> 6 | G16: =COUNTIFS('Gantt Cutover'!$B$6:$B$63,$B16,'Gantt Cutover'!$D$6:$D$63,"<>Fase",'Gantt Cutover'!$M$6:$M$63,"En curso") -> 0 | H16: =COUNTIFS('Gantt Cutover'!$B$6:$B$63,$B16,'Gantt Cutover'!$D$6:$D$63,"<>Fase",'Gantt Cutover'!$M$6:$M$63,"Demorado") -> 0 | I16: =COUNTIFS('Gantt Cutover'!$B$6:$B$63,$B16,'Gantt Cutover'!$D$6:$D$63,"<>Fase",'Gantt Cutover'!$M$6:$M$63,"Finalizado") -> 0 | J16: =IFERROR(I16/E16,0) -> 0 | K16: =COUNTIFS('Gantt Cutover'!$B$6:$B$63,$B16,'Gantt Cutover'!$N$6:$N$63,"Vencida") -> 0 | L16: ='Gantt Cutover'!M41 -> No iniciado
B17: 7. Go / No-Go y entrada en vivo | C17: ='Gantt Cutover'!J48 -> 46333 | D17: ='Gantt Cutover'!K48 -> 46335 | E17: =COUNTIFS('Gantt Cutover'!$B$6:$B$63,$B17,'Gantt Cutover'!$D$6:$D$63,"<>Fase") -> 4 | F17: =COUNTIFS('Gantt Cutover'!$B$6:$B$63,$B17,'Gantt Cutover'!$D$6:$D$63,"<>Fase",'Gantt Cutover'!$M$6:$M$63,"No iniciado") -> 4 | G17: =COUNTIFS('Gantt Cutover'!$B$6:$B$63,$B17,'Gantt Cutover'!$D$6:$D$63,"<>Fase",'Gantt Cutover'!$M$6:$M$63,"En curso") -> 0 | H17: =COUNTIFS('Gantt Cutover'!$B$6:$B$63,$B17,'Gantt Cutover'!$D$6:$D$63,"<>Fase",'Gantt Cutover'!$M$6:$M$63,"Demorado") -> 0 | I17: =COUNTIFS('Gantt Cutover'!$B$6:$B$63,$B17,'Gantt Cutover'!$D$6:$D$63,"<>Fase",'Gantt Cutover'!$M$6:$M$63,"Finalizado") -> 0 | J17: =IFERROR(I17/E17,0) -> 0 | K17: =COUNTIFS('Gantt Cutover'!$B$6:$B$63,$B17,'Gantt Cutover'!$N$6:$N$63,"Vencida") -> 0 | L17: ='Gantt Cutover'!M48 -> No iniciado
B18: 8. Regularización de operaciones | C18: ='Gantt Cutover'!J53 -> 46335 | D18: ='Gantt Cutover'!K53 -> 46338 | E18: =COUNTIFS('Gantt Cutover'!$B$6:$B$63,$B18,'Gantt Cutover'!$D$6:$D$63,"<>Fase") -> 4 | F18: =COUNTIFS('Gantt Cutover'!$B$6:$B$63,$B18,'Gantt Cutover'!$D$6:$D$63,"<>Fase",'Gantt Cutover'!$M$6:$M$63,"No iniciado") -> 4 | G18: =COUNTIFS('Gantt Cutover'!$B$6:$B$63,$B18,'Gantt Cutover'!$D$6:$D$63,"<>Fase",'Gantt Cutover'!$M$6:$M$63,"En curso") -> 0 | H18: =COUNTIFS('Gantt Cutover'!$B$6:$B$63,$B18,'Gantt Cutover'!$D$6:$D$63,"<>Fase",'Gantt Cutover'!$M$6:$M$63,"Demorado") -> 0 | I18: =COUNTIFS('Gantt Cutover'!$B$6:$B$63,$B18,'Gantt Cutover'!$D$6:$D$63,"<>Fase",'Gantt Cutover'!$M$6:$M$63,"Finalizado") -> 0 | J18: =IFERROR(I18/E18,0) -> 0 | K18: =COUNTIFS('Gantt Cutover'!$B$6:$B$63,$B18,'Gantt Cutover'!$N$6:$N$63,"Vencida") -> 0 | L18: ='Gantt Cutover'!M53 -> No iniciado
B19: 9. Hypercare y soporte | C19: ='Gantt Cutover'!J58 -> 46335 | D19: ='Gantt Cutover'!K58 -> 46346 | E19: =COUNTIFS('Gantt Cutover'!$B$6:$B$63,$B19,'Gantt Cutover'!$D$6:$D$63,"<>Fase") -> 5 | F19: =COUNTIFS('Gantt Cutover'!$B$6:$B$63,$B19,'Gantt Cutover'!$D$6:$D$63,"<>Fase",'Gantt Cutover'!$M$6:$M$63,"No iniciado") -> 5 | G19: =COUNTIFS('Gantt Cutover'!$B$6:$B$63,$B19,'Gantt Cutover'!$D$6:$D$63,"<>Fase",'Gantt Cutover'!$M$6:$M$63,"En curso") -> 0 | H19: =COUNTIFS('Gantt Cutover'!$B$6:$B$63,$B19,'Gantt Cutover'!$D$6:$D$63,"<>Fase",'Gantt Cutover'!$M$6:$M$63,"Demorado") -> 0 | I19: =COUNTIFS('Gantt Cutover'!$B$6:$B$63,$B19,'Gantt Cutover'!$D$6:$D$63,"<>Fase",'Gantt Cutover'!$M$6:$M$63,"Finalizado") -> 0 | J19: =IFERROR(I19/E19,0) -> 0 | K19: =COUNTIFS('Gantt Cutover'!$B$6:$B$63,$B19,'Gantt Cutover'!$N$6:$N$63,"Vencida") -> 0 | L19: ='Gantt Cutover'!M58 -> No iniciado
B21: Hitos
B22: Hito | C22: Fecha | D22: Responsable | E22: Estado | F22: Días restantes
B23: ='Gantt Cutover'!C15 -> Validación de Modelos de Negocio y Facturación Electrónica | C23: ='Gantt Cutover'!J15 -> 46325 | D23: ='Gantt Cutover'!G15 -> Jefe de Implementación | E23: ='Gantt Cutover'!M15 -> No iniciado | F23: =C23-Hoy!$C$4 -> 2
B24: ='Gantt Cutover'!C18 -> Cierre de planillas de datos maestros del negocio | C24: ='Gantt Cutover'!J18 -> 46325 | D24: ='Gantt Cutover'!G18 -> Gerente de Contabilidad Regional | E24: ='Gantt Cutover'!M18 -> En curso | F24: =C24-Hoy!$C$4 -> 2
B25: ='Gantt Cutover'!C20 -> Planillas de carga aprobadas | C25: ='Gantt Cutover'!J20 -> 46328 | D25: ='Gantt Cutover'!G20 -> Gerente de Contabilidad Regional | E25: ='Gantt Cutover'!M20 -> No iniciado | F25: =C25-Hoy!$C$4 -> 5
B26: ='Gantt Cutover'!C23 -> Cierre de registros del sistema actual | C26: ='Gantt Cutover'!J23 -> 46323 | D26: ='Gantt Cutover'!G23 -> Contabilidad Colombia | E26: ='Gantt Cutover'!M23 -> En curso | F26: =C26-Hoy!$C$4 -> 0
B27: ='Gantt Cutover'!C27 -> Cierre contable con saldos cuadrados | C27: ='Gantt Cutover'!J27 -> 46330 | D27: ='Gantt Cutover'!G27 -> Gerente de Contabilidad Regional | E27: ='Gantt Cutover'!M27 -> No iniciado | F27: =C27-Hoy!$C$4 -> 7
B28: ='Gantt Cutover'!C40 -> Datos maestros cargados y validados | C28: ='Gantt Cutover'!J40 -> 46330 | D28: ='Gantt Cutover'!G40 -> Gerente de Contabilidad Regional | E28: ='Gantt Cutover'!M40 -> No iniciado | F28: =C28-Hoy!$C$4 -> 7
B29: ='Gantt Cutover'!C47 -> Saldos iniciales cargados | C29: ='Gantt Cutover'!J47 -> 46332 | D29: ='Gantt Cutover'!G47 -> Gerente de Contabilidad Regional | E29: ='Gantt Cutover'!M47 -> No iniciado | F29: =C29-Hoy!$C$4 -> 9
B30: ='Gantt Cutover'!C50 -> Reunión de Go / No-Go | C30: ='Gantt Cutover'!J50 -> 46333 | D30: ='Gantt Cutover'!G50 -> Comité de Proyecto | E30: ='Gantt Cutover'!M50 -> No iniciado | F30: =C30-Hoy!$C$4 -> 10
B31: ='Gantt Cutover'!C51 -> Go-Live: apertura de SAP a los usuarios | C31: ='Gantt Cutover'!J51 -> 46335 | D31: ='Gantt Cutover'!G51 -> Gerente de Proyecto | E31: ='Gantt Cutover'!M51 -> No iniciado | F31: =C31-Hoy!$C$4 -> 12
B32: ='Gantt Cutover'!C52 -> Primera factura electrónica emitida desde SAP | C32: ='Gantt Cutover'!J52 -> 46335 | D32: ='Gantt Cutover'!G52 -> Comercial / Facturación Colombia | E32: ='Gantt Cutover'!M52 -> No iniciado | F32: =C32-Hoy!$C$4 -> 12
B33: ='Gantt Cutover'!C57 -> Regularización de Operaciones Finalizada | C33: ='Gantt Cutover'!J57 -> 46338 | D33: ='Gantt Cutover'!G57 -> Gerente de Contabilidad Regional | E33: ='Gantt Cutover'!M57 -> No iniciado | F33: =C33-Hoy!$C$4 -> 15
B34: ='Gantt Cutover'!C63 -> Cierre del Hypercare y traspaso a soporte continuo | C34: ='Gantt Cutover'!J63 -> 46346 | D34: ='Gantt Cutover'!G63 -> Comité de Proyecto | E34: ='Gantt Cutover'!M63 -> No iniciado | F34: =C34-Hoy!$C$4 -> 23
B36: Estado por frente
B37: Frente | C37: Total | D37: No iniciado | E37: En curso | F37: Demorado | G37: Finalizado | H37: Vencidas
B38: PMO | C38: =COUNTIFS('Gantt Cutover'!$F$6:$F$63,$B38,'Gantt Cutover'!$D$6:$D$63,"<>Fase") -> 9 | D38: =COUNTIFS('Gantt Cutover'!$F$6:$F$63,$B38,'Gantt Cutover'!$D$6:$D$63,"<>Fase",'Gantt Cutover'!$M$6:$M$63,"No iniciado") -> 9 | E38: =COUNTIFS('Gantt Cutover'!$F$6:$F$63,$B38,'Gantt Cutover'!$D$6:$D$63,"<>Fase",'Gantt Cutover'!$M$6:$M$63,"En curso") -> 0 | F38: =COUNTIFS('Gantt Cutover'!$F$6:$F$63,$B38,'Gantt Cutover'!$D$6:$D$63,"<>Fase",'Gantt Cutover'!$M$6:$M$63,"Demorado") -> 0 | G38: =COUNTIFS('Gantt Cutover'!$F$6:$F$63,$B38,'Gantt Cutover'!$D$6:$D$63,"<>Fase",'Gantt Cutover'!$M$6:$M$63,"Finalizado") -> 0 | H38: =COUNTIFS('Gantt Cutover'!$F$6:$F$63,$B38,'Gantt Cutover'!$N$6:$N$63,"Vencida") -> 0
B39: Negocio | C39: =COUNTIFS('Gantt Cutover'!$F$6:$F$63,$B39,'Gantt Cutover'!$D$6:$D$63,"<>Fase") -> 9 | D39: =COUNTIFS('Gantt Cutover'!$F$6:$F$63,$B39,'Gantt Cutover'!$D$6:$D$63,"<>Fase",'Gantt Cutover'!$M$6:$M$63,"No iniciado") -> 4 | E39: =COUNTIFS('Gantt Cutover'!$F$6:$F$63,$B39,'Gantt Cutover'!$D$6:$D$63,"<>Fase",'Gantt Cutover'!$M$6:$M$63,"En curso") -> 5 | F39: =COUNTIFS('Gantt Cutover'!$F$6:$F$63,$B39,'Gantt Cutover'!$D$6:$D$63,"<>Fase",'Gantt Cutover'!$M$6:$M$63,"Demorado") -> 0 | G39: =COUNTIFS('Gantt Cutover'!$F$6:$F$63,$B39,'Gantt Cutover'!$D$6:$D$63,"<>Fase",'Gantt Cutover'!$M$6:$M$63,"Finalizado") -> 0 | H39: =COUNTIFS('Gantt Cutover'!$F$6:$F$63,$B39,'Gantt Cutover'!$N$6:$N$63,"Vencida") -> 0
B40: Financiero | C40: =COUNTIFS('Gantt Cutover'!$F$6:$F$63,$B40,'Gantt Cutover'!$D$6:$D$63,"<>Fase") -> 15 | D40: =COUNTIFS('Gantt Cutover'!$F$6:$F$63,$B40,'Gantt Cutover'!$D$6:$D$63,"<>Fase",'Gantt Cutover'!$M$6:$M$63,"No iniciado") -> 15 | E40: =COUNTIFS('Gantt Cutover'!$F$6:$F$63,$B40,'Gantt Cutover'!$D$6:$D$63,"<>Fase",'Gantt Cutover'!$M$6:$M$63,"En curso") -> 0 | F40: =COUNTIFS('Gantt Cutover'!$F$6:$F$63,$B40,'Gantt Cutover'!$D$6:$D$63,"<>Fase",'Gantt Cutover'!$M$6:$M$63,"Demorado") -> 0 | G40: =COUNTIFS('Gantt Cutover'!$F$6:$F$63,$B40,'Gantt Cutover'!$D$6:$D$63,"<>Fase",'Gantt Cutover'!$M$6:$M$63,"Finalizado") -> 0 | H40: =COUNTIFS('Gantt Cutover'!$F$6:$F$63,$B40,'Gantt Cutover'!$N$6:$N$63,"Vencida") -> 0
B41: Logístico | C41: =COUNTIFS('Gantt Cutover'!$F$6:$F$63,$B41,'Gantt Cutover'!$D$6:$D$63,"<>Fase") -> 6 | D41: =COUNTIFS('Gantt Cutover'!$F$6:$F$63,$B41,'Gantt Cutover'!$D$6:$D$63,"<>Fase",'Gantt Cutover'!$M$6:$M$63,"No iniciado") -> 6 | E41: =COUNTIFS('Gantt Cutover'!$F$6:$F$63,$B41,'Gantt Cutover'!$D$6:$D$63,"<>Fase",'Gantt Cutover'!$M$6:$M$63,"En curso") -> 0 | F41: =COUNTIFS('Gantt Cutover'!$F$6:$F$63,$B41,'Gantt Cutover'!$D$6:$D$63,"<>Fase",'Gantt Cutover'!$M$6:$M$63,"Demorado") -> 0 | G41: =COUNTIFS('Gantt Cutover'!$F$6:$F$63,$B41,'Gantt Cutover'!$D$6:$D$63,"<>Fase",'Gantt Cutover'!$M$6:$M$63,"Finalizado") -> 0 | H41: =COUNTIFS('Gantt Cutover'!$F$6:$F$63,$B41,'Gantt Cutover'!$N$6:$N$63,"Vencida") -> 0
B42: Localización-FFEE | C42: =COUNTIFS('Gantt Cutover'!$F$6:$F$63,$B42,'Gantt Cutover'!$D$6:$D$63,"<>Fase") -> 3 | D42: =COUNTIFS('Gantt Cutover'!$F$6:$F$63,$B42,'Gantt Cutover'!$D$6:$D$63,"<>Fase",'Gantt Cutover'!$M$6:$M$63,"No iniciado") -> 2 | E42: =COUNTIFS('Gantt Cutover'!$F$6:$F$63,$B42,'Gantt Cutover'!$D$6:$D$63,"<>Fase",'Gantt Cutover'!$M$6:$M$63,"En curso") -> 1 | F42: =COUNTIFS('Gantt Cutover'!$F$6:$F$63,$B42,'Gantt Cutover'!$D$6:$D$63,"<>Fase",'Gantt Cutover'!$M$6:$M$63,"Demorado") -> 0 | G42: =COUNTIFS('Gantt Cutover'!$F$6:$F$63,$B42,'Gantt Cutover'!$D$6:$D$63,"<>Fase",'Gantt Cutover'!$M$6:$M$63,"Finalizado") -> 0 | H42: =COUNTIFS('Gantt Cutover'!$F$6:$F$63,$B42,'Gantt Cutover'!$N$6:$N$63,"Vencida") -> 0
B43: Técnico | C43: =COUNTIFS('Gantt Cutover'!$F$6:$F$63,$B43,'Gantt Cutover'!$D$6:$D$63,"<>Fase") -> 6 | D43: =COUNTIFS('Gantt Cutover'!$F$6:$F$63,$B43,'Gantt Cutover'!$D$6:$D$63,"<>Fase",'Gantt Cutover'!$M$6:$M$63,"No iniciado") -> 5 | E43: =COUNTIFS('Gantt Cutover'!$F$6:$F$63,$B43,'Gantt Cutover'!$D$6:$D$63,"<>Fase",'Gantt Cutover'!$M$6:$M$63,"En curso") -> 1 | F43: =COUNTIFS('Gantt Cutover'!$F$6:$F$63,$B43,'Gantt Cutover'!$D$6:$D$63,"<>Fase",'Gantt Cutover'!$M$6:$M$63,"Demorado") -> 0 | G43: =COUNTIFS('Gantt Cutover'!$F$6:$F$63,$B43,'Gantt Cutover'!$D$6:$D$63,"<>Fase",'Gantt Cutover'!$M$6:$M$63,"Finalizado") -> 0 | H43: =COUNTIFS('Gantt Cutover'!$F$6:$F$63,$B43,'Gantt Cutover'!$N$6:$N$63,"Vencida") -> 0

Sheet Hoy
A1: Actividades del día
A2: Escriba la fecha en la celda amarilla (por defecto, la fecha actual) y la hoja muestra lo que debe estar ocurriendo ese día y quién participa.
B4: Fecha de consulta | C4: =TODAY() -> 46323
B5: Días al Go-Live | C5: ='Equipo y Calendario'!$B$28-C4 -> 12
B6: Equipo en sitio | C6: =IF(AND(C4>='Equipo y Calendario'!$B$29,C4<='Equipo y Calendario'!$B$30),"Sí – Bogotá","No") -> No
B7: Día no hábil | C7: =IF(COUNTIF('Equipo y Calendario'!$B$33:$B$38,C4)>0,"Feriado en Colombia",IF(WEEKDAY(C4,2)>5,"Fin de semana","Día hábil")) -> Día hábil
B8: Actividades del día | C8: =SUM('Gantt Cutover'!$AX$6:$AX$63) -> 5
B9: Actividades vencidas | C9: =SUM('Gantt Cutover'!$AZ$6:$AZ$63) -> 0
B12: Lo que debe estar ocurriendo en la fecha
B13: # | C13: ID | D13: Fase | E13: Actividad / hito | F13: Responsable | G13: Nombre responsable | H13: Participantes | I13: Modalidad | J13: Inicio | K13: Fin | L13: Estado
B14: 1 | C14: =IFERROR(INDEX('Gantt Cutover'!$A$6:$A$63,MATCH(1,'Gantt Cutover'!$AY$6:$AY$63,0)),"") -> C06 | D14: =IFERROR(INDEX('Gantt Cutover'!$B$6:$B$63,MATCH(1,'Gantt Cutover'!$AY$6:$AY$63,0)),"") -> 1. Pruebas y Validación Modelos de Negocios | E14: =IFERROR(INDEX('Gantt Cutover'!$C$6:$C$63,MATCH(1,'Gantt Cutover'!$AY$6:$AY$63,0)),"") -> Pruebas y ajustes a Modelos de Negocio | F14: =IFERROR(INDEX('Gantt Cutover'!$G$6:$G$63,MATCH(1,'Gantt Cutover'!$AY$6:$AY$63,0)),"") -> Jefe de Implementación | G14: =IFERROR(INDEX('Equipo y Calendario'!$B$5:$B$24,MATCH(F14,'Equipo y Calendario'!$A$5:$A$24,0)),"") -> Jorge Muñoz | H14: =IFERROR(INDEX('Gantt Cutover'!$H$6:$H$63,MATCH(1,'Gantt Cutover'!$AY$6:$AY$63,0)),"") -> Implementador – Consultor FI/CO; Implementador – Consultor MM/SD; TI Portland FICO; TI Portland MM; Contabilidad Colombia; Comercial / Facturación Colombia; Logística / Bodega Colombia | I14: =IFERROR(INDEX('Gantt Cutover'!$I$6:$I$63,MATCH(1,'Gantt Cutover'!$AY$6:$AY$63,0)),"") -> Remoto | J14: =IFERROR(INDEX('Gantt Cutover'!$J$6:$J$63,MATCH(1,'Gantt Cutover'!$AY$6:$AY$63,0)),"") -> 46321 | K14: =IFERROR(INDEX('Gantt Cutover'!$K$6:$K$63,MATCH(1,'Gantt Cutover'!$AY$6:$AY$63,0)),"") -> 46325 | L14: =IFERROR(INDEX('Gantt Cutover'!$M$6:$M$63,MATCH(1,'Gantt Cutover'!$AY$6:$AY$63,0)),"") -> En curso
B15: 2 | C15: =IFERROR(INDEX('Gantt Cutover'!$A$6:$A$63,MATCH(2,'Gantt Cutover'!$AY$6:$AY$63,0)),"") -> C07 | D15: =IFERROR(INDEX('Gantt Cutover'!$B$6:$B$63,MATCH(2,'Gantt Cutover'!$AY$6:$AY$63,0)),"") -> 1. Pruebas y Validación Modelos de Negocios | E15: =IFERROR(INDEX('Gantt Cutover'!$C$6:$C$63,MATCH(2,'Gantt Cutover'!$AY$6:$AY$63,0)),"") -> Pruebas y Ajustes a FFEE | F15: =IFERROR(INDEX('Gantt Cutover'!$G$6:$G$63,MATCH(2,'Gantt Cutover'!$AY$6:$AY$63,0)),"") -> Jefe de Implementación | G15: =IFERROR(INDEX('Equipo y Calendario'!$B$5:$B$24,MATCH(F15,'Equipo y Calendario'!$A$5:$A$24,0)),"") -> Jorge Muñoz | H15: =IFERROR(INDEX('Gantt Cutover'!$H$6:$H$63,MATCH(2,'Gantt Cutover'!$AY$6:$AY$63,0)),"") -> TI Portland SD y FFEE; Implementador – FFEE/Formularios | I15: =IFERROR(INDEX('Gantt Cutover'!$I$6:$I$63,MATCH(2,'Gantt Cutover'!$AY$6:$AY$63,0)),"") -> Remoto | J15: =IFERROR(INDEX('Gantt Cutover'!$J$6:$J$63,MATCH(2,'Gantt Cutover'!$AY$6:$AY$63,0)),"") -> 46321 | K15: =IFERROR(INDEX('Gantt Cutover'!$K$6:$K$63,MATCH(2,'Gantt Cutover'!$AY$6:$AY$63,0)),"") -> 46325 | L15: =IFERROR(INDEX('Gantt Cutover'!$M$6:$M$63,MATCH(2,'Gantt Cutover'!$AY$6:$AY$63,0)),"") -> En curso
B16: 3 | C16: =IFERROR(INDEX('Gantt Cutover'!$A$6:$A$63,MATCH(3,'Gantt Cutover'!$AY$6:$AY$63,0)),"") -> C14 | D16: =IFERROR(INDEX('Gantt Cutover'!$B$6:$B$63,MATCH(3,'Gantt Cutover'!$AY$6:$AY$63,0)),"") -> 3. Cierre del sistema actual | E16: =IFERROR(INDEX('Gantt Cutover'!$C$6:$C$63,MATCH(3,'Gantt Cutover'!$AY$6:$AY$63,0)),"") -> Registro de últimas operaciones en sistema actual | F16: =IFERROR(INDEX('Gantt Cutover'!$G$6:$G$63,MATCH(3,'Gantt Cutover'!$AY$6:$AY$63,0)),"") -> Contabilidad Colombia | G16: =IFERROR(INDEX('Equipo y Calendario'!$B$5:$B$24,MATCH(F16,'Equipo y Calendario'!$A$5:$A$24,0)),"") -> Camila Castiblanco | H16: =IFERROR(INDEX('Gantt Cutover'!$H$6:$H$63,MATCH(3,'Gantt Cutover'!$AY$6:$AY$63,0)),"") -> Comercial / Facturación Colombia; Logística / Bodega Colombia; Tesorería Colombia | I16: =IFERROR(INDEX('Gantt Cutover'!$I$6:$I$63,MATCH(3,'Gantt Cutover'!$AY$6:$AY$63,0)),"") -> Remoto | J16: =IFERROR(INDEX('Gantt Cutover'!$J$6:$J$63,MATCH(3,'Gantt Cutover'!$AY$6:$AY$63,0)),"") -> 46321 | K16: =IFERROR(INDEX('Gantt Cutover'!$K$6:$K$63,MATCH(3,'Gantt Cutover'!$AY$6:$AY$63,0)),"") -> 46323 | L16: =IFERROR(INDEX('Gantt Cutover'!$M$6:$M$63,MATCH(3,'Gantt Cutover'!$AY$6:$AY$63,0)),"") -> En curso
